Workbook

Sheet Legend
A1: Bảng so sánh thí nghiệm — Lab Day 1
A2: Lưu file này thành experiments.xlsx. Mỗi lần chạy là một dòng ở sheet Experiments (số dòng tuỳ bạn, có sẵn 60 dòng). Sheet Seeds và Summary tự tổng hợp.
A4: Quy ước màu
B5: Ô vàng: bạn điền (cấu hình và kết quả đo).
A6: abc | B6: Chữ xanh dương: giá trị đã điền sẵn cho dòng baseline; bạn có thể sửa.
B7: Ô xám: công thức tự tính. Không sửa.
A9: Cách dùng
A10: 1. Sheet Experiments: dòng đầu là baseline mẫu. Điền lr và kết quả; thêm dòng cho mỗi thí nghiệm khác.
A11: 2. Mỗi dòng phải có ảnh riêng figures/<exp_id>.png. Điền tên file vào cột figure_file.
A12: 3. Sheet Seeds: nhập exp_id của các lần chạy baseline với seed khác nhau (đã gợi ý base-s1..3). Sheet tự tính trung bình, σ và 2σ.
A13: 4. Cột beyond_noise cho biết chênh lệch val_macro_f1 so với baseline có vượt 2σ không. Chỉ 'Có' mới là bằng chứng.
A14: 5. Sheet Summary: số dòng theo nhóm và số chủ đề (trong 7) đã được thử.
A16: Từ điển cột (sheet Experiments)
A17: Cột | B17: Ý nghĩa | C17: Cách điền
A18: exp_id | B18: Mã thí nghiệm, duy nhất; trùng tên file ảnh | C18: Tự đặt, ví dụ base-s1, opt-adam-lr1e-3, drop-0.3.
A19: group | B19: Nhóm: baseline | loss | optimizer | hparam | dropout | clipping | amp | init | final | other | C19: Chọn từ danh sách.
A20: description | B20: Bạn đổi gì so với baseline | C20: Một câu.
A21: loss | B21: Hàm mất mát: CE | MSE | C21: Chọn từ danh sách.
A22: optimizer | B22: SGD | SGD+momentum | Adam | AdamW | C22: Chọn từ danh sách.
A23: lr | B23: Tốc độ học η | C23: Ghi số, ví dụ 0.05 hoặc 1e-3.
A24: weight_decay | B24: Hệ số suy giảm trọng số λ | C24: 0 nếu không dùng.
A25: batch | B25: Kích thước lô | C25: Số nguyên.
A26: epochs | B26: Số epoch | C26: Khuyến nghị 20 cho mọi thí nghiệm.
A27: hidden | B27: Các lớp ẩn, ví dụ 256-128 | C27: Chuỗi nối bằng dấu gạch.
A28: dropout | B28: Xác suất tắt nơ-ron q | C28: 0 nếu không dùng.
... A33: step0_loss | B33: Loss trên val ở bước 0 (trước cập nhật đầu tiên) | C33: Kỳ vọng ≈ ln 7 = 1.946 nếu khởi tạo hợp lý.
A34: best_val_loss | B34: Val loss thấp nhất qua các epoch
A35: best_epoch | B35: Epoch đạt best_val_loss | C35: Đếm từ 1.
A36: final_train_loss | B36: Train loss ở epoch cuối (đo ở chế độ eval)
A37: final_val_loss | B37: Val loss ở epoch cuối
A38: val_acc | B38: Val accuracy ở best_epoch | C38: Phân số 0–1, ví dụ 0.8123.
A39: val_macro_f1 | B39: Val macro-F1 ở best_epoch | C39: Phân số 0–1.
A40: time_per_epoch_s | B40: Thời gian trung bình mỗi epoch (giây) | C40: Có torch.cuda.synchronize().
A41: peak_mem_MB | B41: Bộ nhớ GPU cực đại (MB) | C41: torch.cuda.max_memory_allocated()/2**20.
A42: diverged | B42: Loss thành NaN/inf? Y | N | C42: Chọn từ danh sách.
A43: eval_acc | B43: Accuracy trên tập eval | C43: CHỈ điền cho baseline và cấu hình cuối cùng, lấy từ eval_result.json.
A44: eval_macro_f1 | B44: macro-F1 trên tập eval | C44: CHỈ điền cho baseline và cấu hình cuối cùng, lấy từ eval_result.json.
A45: figure_file | B45: Tên file ảnh | C45: figures/<exp_id>.png
A46: notes | B46: Ghi chú | C46: Dự đoán trước, quan sát, lý do thiếu số liệu, lỗi gặp phải...
A47: step0_gap_vs_lnC | B47: step0_loss − ln 7 | C47: Tự tính. Gần 0 là tốt.
...

Sheet Experiments
A1: exp_id | B1: group | C1: description | D1: loss | E1: optimizer | F1: lr | G1: weight_decay | H1: batch | I1: epochs | J1: hidden | K1: dropout | L1: clip_norm | M1: precision | N1: init | O1: seed | P1: step0_loss | Q1: best_val_loss | R1: best_epoch | S1: final_train_loss | T1: final_val_loss | U1: val_acc | V1: val_macro_f1 | W1: time_per_epoch_s | X1: peak_mem_MB | Y1: diverged | Z1: eval_acc | AA1: eval_macro_f1 | AB1: figure_file | AC1: notes | AD1: step0_gap_vs_lnC | AE1: gap_val_minus_train | AF1: delta_val_f1_vs_base | AG1: beyond_noise
A2: lr-sgd-0.01 | B2: hparam | C2: SGD momentum learning-rate pilot lr=0.01; 4 epochs | D2: ce | E2: sgd_momentum | F2: 0.01 | G2: 0 | H2: 512 | I2: 4 | J2: 256-128 | K2: 0 | M2: fp32 | N2: he | O2: 1 | P2: 2.2690618 | Q2: 0.48059255 | R2: 4 | S2: 0.47517678 | T2: 0.48059255 | U2: 0.79747639 | V2: 0.63139425 | W2: 2.2315143 | X2: 0 | Y2: FALSE | AB2: figures/lr-sgd-0.01.png | AD2: =IF(P2="","",P2-LN(7)) -> 0.32315166 | AE2: =IF(OR(T2="",S2=""),"",T2-S2) -> 0.0054157734 | AF2: =IF(OR(V2="",Seeds!$C$8=""),"",V2-Seeds!$C$8) -> -0.21473973 | AG2: =IF(OR(AF2="",Seeds!$C$10=""),"",IF(ABS(AF2)>Seeds!$C$10,"Có","Không")) -> Có
A3: lr-sgd-0.03 | B3: hparam | C3: SGD momentum learning-rate pilot lr=0.03; 4 epochs | D3: ce | E3: sgd_momentum | F3: 0.03 | G3: 0 | H3: 512 | I3: 4 | J3: 256-128 | K3: 0 | M3: fp32 | N3: he | O3: 1 | P3: 2.2690618 | Q3: 0.39755385 | R3: 4 | S3: 0.39053156 | T3: 0.39755385 | U3: 0.83044685 | V3: 0.71328904 | W3: 2.1662043 | X3: 0 | Y3: FALSE | AB3: figures/lr-sgd-0.03.png | AD3: =IF(P3="","",P3-LN(7)) -> 0.32315166 | AE3: =IF(OR(T3="",S3=""),"",T3-S3) -> 0.0070222945 | AF3: =IF(OR(V3="",Seeds!$C$8=""),"",V3-Seeds!$C$8) -> -0.13284494 | AG3: =IF(OR(AF3="",Seeds!$C$10=""),"",IF(ABS(AF3)>Seeds!$C$10,"Có","Không")) -> Có
A4: lr-sgd-0.06 | B4: hparam | C4: SGD momentum learning-rate pilot lr=0.06; 4 epochs | D4: ce | E4: sgd_momentum | F4: 0.06 | G4: 0 | H4: 512 | I4: 4 | J4: 256-128 | K4: 0 | M4: fp32 | N4: he | O4: 1 | P4: 2.2690618 | Q4: 0.37444899 | R4: 4 | S4: 0.36707683 | T4: 0.37444899 | U4: 0.84276371 | V4: 0.73965124 | W4: 2.2859483 | X4: 0 | Y4: FALSE | AB4: figures/lr-sgd-0.06.png | AD4: =IF(P4="","",P4-LN(7)) -> 0.32315166 | AE4: =IF(OR(T4="",S4=""),"",T4-S4) -> 0.0073721637 | AF4: =IF(OR(V4="",Seeds!$C$8=""),"",V4-Seeds!$C$8) -> -0.10648274 | AG4: =IF(OR(AF4="",Seeds!$C$10=""),"",IF(ABS(AF4)>Seeds!$C$10,"Có","Không")) -> Có
A5: lr-adam-0.001 | B5: optimizer | C5: Adam learning-rate pilot lr=0.001; 4 epochs | D5: ce | E5: adam | F5: 0.001 | G5: 0 | H5: 512 | I5: 4 | J5: 256-128 | K5: 0 | M5: fp32 | N5: he | O5: 1 | P5: 2.2690618 | Q5: 0.37063025 | R5: 4 | S5: 0.36243914 | T5: 0.37063025 | U5: 0.84542071 | V5: 0.74906728 | W5: 3.0270311 | X5: 0 | Y5: FALSE | AB5: figures/lr-adam-0.001.png | AD5: =IF(P5="","",P5-LN(7)) -> 0.32315166 | AE5: =IF(OR(T5="",S5=""),"",T5-S5) -> 0.0081911104 | AF5: =IF(OR(V5="",Seeds!$C$8=""),"",V5-Seeds!$C$8) -> -0.097066708 | AG5: =IF(OR(AF5="",Seeds!$C$10=""),"",IF(ABS(AF5)>Seeds!$C$10,"Có","Không")) -> Có
A6: lr-adam-0.003 | B6: optimizer | C6: Adam learning-rate pilot lr=0.003; 4 epochs | D6: ce | E6: adam | F6: 0.003 | G6: 0 | H6: 512 | I6: 4 | J6: 256-128 | K6: 0 | M6: fp32 | N6: he | O6: 1 | P6: 2.2690618 | Q6: 0.3172706 | R6: 4 | S6: 0.30753012 | T6: 0.3172706 | U6: 0.86892494 | V6: 0.7912829 | W6: 2.9608649 | X6: 0 | Y6: FALSE | AB6: figures/lr-adam-0.003.png | AD6: =IF(P6="","",P6-LN(7)) -> 0.32315166 | AE6: =IF(OR(T6="",S6=""),"",T6-S6) -> 0.0097404752 | AF6: =IF(OR(V6="",Seeds!$C$8=""),"",V6-Seeds!$C$8) -> -0.054851084 | AG6: =IF(OR(AF6="",Seeds!$C$10=""),"",IF(ABS(AF6)>Seeds!$C$10,"Có","Không")) -> Có
A7: base-s1 | B7: baseline | C7: M-base; CE; SGD momentum 0.9; He | D7: ce | E7: sgd_momentum | F7: 0.06 | G7: 0 | H7: 512 | I7: 20 | J7: 256-128 | K7: 0 | M7: fp32 | N7: he | O7: 1 | P7: 2.2690618 | Q7: 0.24404185 | R7: 19 | S7: 0.22526151 | T7: 0.24404185 | U7: 0.90158344 | V7: 0.84509488 | W7: 2.7002247 | X7: 0 | Y7: FALSE | Z7: 0.90095781 | AA7: 0.84734064 | AB7: figures/base-s1.png | AD7: =IF(P7="","",P7-LN(7)) -> 0.32315166 | AE7: =IF(OR(T7="",S7=""),"",T7-S7) -> 0.018780338 | AF7: =IF(OR(V7="",Seeds!$C$8=""),"",V7-Seeds!$C$8) -> -0.001039106 | AG7: =IF(OR(AF7="",Seeds!$C$10=""),"",IF(ABS(AF7)>Seeds!$C$10,"Có","Không")) -> Không
A8: base-s2 | B8: baseline | C8: M-base baseline, seed 2 | D8: ce | E8: sgd_momentum | F8: 0.06 | G8: 0 | H8: 512 | I8: 20 | J8: 256-128 | K8: 0 | M8: fp32 | N8: he | O8: 2 | P8: 1.9781567 | Q8: 0.249117 | R8: 20 | S8: 0.22799294 | T8: 0.249117 | U8: 0.89949657 | V8: 0.84717309 | W8: 2.3116892 | X8: 0 | Y8: FALSE | AB8: figures/base-s2.png | AD8: =IF(P8="","",P8-LN(7)) -> 0.032246542 | AE8: =IF(OR(T8="",S8=""),"",T8-S8) -> 0.021124063 | AF8: =IF(OR(V8="",Seeds!$C$8=""),"",V8-Seeds!$C$8) -> 0.001039106 | AG8: =IF(OR(AF8="",Seeds!$C$10=""),"",IF(ABS(AF8)>Seeds!$C$10,"Có","Không")) -> Không
A9: loss-mse | B9: loss | C9: MSE loss vs baseline CE | D9: mse | E9: sgd_momentum | F9: 0.06 | G9: 0 | H9: 512 | I9: 20 | J9: 256-128 | K9: 0 | M9: fp32 | N9: he | O9: 1 | P9: 0.63585031 | Q9: 0.031372856 | R9: 20 | S9: 0.030525488 | T9: 0.031372856 | U9: 0.86117984 | V9: 0.70974256 | W9: 2.1915869 | X9: 0 | Y9: FALSE | AB9: figures/loss-mse.png | AD9: =IF(P9="","",P9-LN(7)) -> -1.3100598 | AE9: =IF(OR(T9="",S9=""),"",T9-S9) -> 0.00084736826 | AF9: =IF(OR(V9="",Seeds!$C$8=""),"",V9-Seeds!$C$8) -> -0.13639142 | AG9: =IF(OR(AF9="",Seeds!$C$10=""),"",IF(ABS(AF9)>Seeds!$C$10,"Có","Không")) -> Có
A10: opt-adam | B10: optimizer | C10: Adam; learning rate selected with validation pilot | D10: ce | E10: adam | F10: 0.003 | G10: 0 | H10: 512 | I10: 20 | J10: 256-128 | K10: 0 | M10: fp32 | N10: he | O10: 1 | P10: 2.2690618 | Q10: 0.20996649 | R10: 20 | S10: 0.18293551 | T10: 0.20996649 | U10: 0.91567522 | V10: 0.87521444 | W10: 2.4268059 | X10: 0 | Y10: FALSE | Z10: 0.9147096 | AA10: 0.8769603 | AB10: figures/opt-adam.png | AD10: =IF(P10="","",P10-LN(7)) -> 0.32315166 | AE10: =IF(OR(T10="",S10=""),"",T10-S10) -> 0.027030974 | AF10: =IF(OR(V10="",Seeds!$C$8=""),"",V10-Seeds!$C$8) -> 0.029080456 | AG10: =IF(OR(AF10="",Seeds!$C$10=""),"",IF(ABS(AF10)>Seeds!$C$10,"Có","Không")) -> Có
A11: hparam-wide | B11: hparam | C11: M-wide (512-256) vs M-base | D11: ce | E11: sgd_momentum | F11: 0.06 | G11: 0 | H11: 512 | I11: 20 | J11: 512-256 | K11: 0 | M11: fp32 | N11: he | O11: 1 | P11: 1.9182165 | Q11: 0.21982841 | R11: 18 | S11: 0.19449283 | T11: 0.21982841 | U11: 0.91273854 | V11: 0.86214622 | W11: 5.5550556 | X11: 0 | Y11: FALSE | AB11: figures/hparam-wide.png | AD11: =IF(P11="","",P11-LN(7)) -> -0.027693618 | AE11: =IF(OR(T11="",S11=""),"",T11-S11) -> 0.025335587 | AF11: =IF(OR(V11="",Seeds!$C$8=""),"",V11-Seeds!$C$8) -> 0.016012236 | AG11: =IF(OR(AF11="",Seeds!$C$10=""),"",IF(ABS(AF11)>Seeds!$C$10,"Có","Không")) -> Có
A12: dropout-03 | B12: dropout | C12: Dropout p=0.3 after hidden ReLUs | D12: ce | E12: sgd_momentum | F12: 0.06 | G12: 0 | H12: 512 | I12: 20 | J12: 256-128 | K12: 0.3 | M12: fp32 | N12: he | O12: 1 | P12: 2.2690618 | Q12: 0.33631232 | R12: 19 | S12: 0.33045166 | T12: 0.33631232 | U12: 0.86140574 | V12: 0.76553455 | W12: 4.2067204 | X12: 0 | Y12: FALSE | AB12: figures/dropout-03.png | AD12: =IF(P12="","",P12-LN(7)) -> 0.32315166 | AE12: =IF(OR(T12="",S12=""),"",T12-S12) -> 0.0058606651 | AF12: =IF(OR(V12="",Seeds!$C$8=""),"",V12-Seeds!$C$8) -> -0.080599435 | AG12: =IF(OR(AF12="",Seeds!$C$10=""),"",IF(ABS(AF12)>Seeds!$C$10,"Có","Không")) -> Có
A13: clip-1 | B13: clipping | C13: Global gradient clipping at norm 1.0 | D13: ce | E13: sgd_momentum | F13: 0.06 | G13: 0 | H13: 512 | I13: 20 | J13: 256-128 | K13: 0 | L13: 1 | M13: fp32 | N13: he | O13: 1 | P13: 2.2690618 | Q13: 0.24325767 | R13: 18 | S13: 0.22447976 | T13: 0.24325767 | U13: 0.90297111 | V13: 0.84404422 | W13: 2.2330046 | X13: 0 | Y13: FALSE | AB13: figures/clip-1.png | AD13: =IF(P13="","",P13-LN(7)) -> 0.32315166 | AE13: =IF(OR(T13="",S13=""),"",T13-S13) -> 0.018777911 | AF13: =IF(OR(V13="",Seeds!$C$8=""),"",V13-Seeds!$C$8) -> -0.0020897631 | AG13: =IF(OR(AF13="",Seeds!$C$10=""),"",IF(ABS(AF13)>Seeds!$C$10,"Có","Không")) -> Không
A14: init-xavier | B14: init | C14: Xavier-normal initialization vs He | D14: ce | E14: sgd_momentum | F14: 0.06 | G14: 0 | H14: 512 | I14: 20 | J14: 256-128 | K14: 0 | M14: fp32 | N14: xavier | O14: 1 | P14: 2.0221762 | Q14: 0.24864954 | R14: 20 | S14: 0.23259293 | T14: 0.24864954 | U14: 0.90044319 | V14: 0.84507672 | W14: 2.255646 | X14: 0 | Y14: FALSE | AB14: figures/init-xavier.png | AD14: =IF(P14="","",P14-LN(7)) -> 0.076266099 | AE14: =IF(OR(T14="",S14=""),"",T14-S14) -> 0.016056613 | AF14: =IF(OR(V14="",Seeds!$C$8=""),"",V14-Seeds!$C$8) -> -0.0010572665 | AG14: =IF(OR(AF14="",Seeds!$C$10=""),"",IF(ABS(AF14)>Seeds!$C$10,"Có","Không")) -> Không

Sheet Seeds
A1: exp_id baseline (nhập) | B1: val_acc | C1: val_macro_f1 | D1: best_val_loss
A2: base-s1 | B2: {=IF($A2="","",IFERROR(IF(INDEX(Experiments!$U$2:$U$61,MATCH($A2,Experiments!$A$2:$A$61,0))="","",INDEX(Experiments!$U$2:$U$61,MATCH($A2,Experiments!$A$2:$A$61,0))),""))} -> 0.90158344 | C2: {=IF($A2="","",IFERROR(IF(INDEX(Experiments!$V$2:$V$61,MATCH($A2,Experiments!$A$2:$A$61,0))="","",INDEX(Experiments!$V$2:$V$61,MATCH($A2,Experiments!$A$2:$A$61,0))),""))} -> 0.84509488 | D2: {=IF($A2="","",IFERROR(IF(INDEX(Experiments!$Q$2:$Q$61,MATCH($A2,Experiments!$A$2:$A$61,0))="","",INDEX(Experiments!$Q$2:$Q$61,MATCH($A2,Experiments!$A$2:$A$61,0))),""))} -> 0.24404185
A3: base-s2 | B3: {=IF($A3="","",IFERROR(IF(INDEX(Experiments!$U$2:$U$61,MATCH($A3,Experiments!$A$2:$A$61,0))="","",INDEX(Experiments!$U$2:$U$61,MATCH($A3,Experiments!$A$2:$A$61,0))),""))} -> 0.89949657 | C3: {=IF($A3="","",IFERROR(IF(INDEX(Experiments!$V$2:$V$61,MATCH($A3,Experiments!$A$2:$A$61,0))="","",INDEX(Experiments!$V$2:$V$61,MATCH($A3,Experiments!$A$2:$A$61,0))),""))} -> 0.84717309 | D3: {=IF($A3="","",IFERROR(IF(INDEX(Experiments!$Q$2:$Q$61,MATCH($A3,Experiments!$A$2:$A$61,0))="","",INDEX(Experiments!$Q$2:$Q$61,MATCH($A3,Experiments!$A$2:$A$61,0))),""))} -> 0.249117
A4: base-s3 | B4: {=IF($A4="","",IFERROR(IF(INDEX(Experiments!$U$2:$U$61,MATCH($A4,Experiments!$A$2:$A$61,0))="","",INDEX(Experiments!$U$2:$U$61,MATCH($A4,Experiments!$A$2:$A$61,0))),""))} | C4: {=IF($A4="","",IFERROR(IF(INDEX(Experiments!$V$2:$V$61,MATCH($A4,Experiments!$A$2:$A$61,0))="","",INDEX(Experiments!$V$2:$V$61,MATCH($A4,Experiments!$A$2:$A$61,0))),""))} | D4: {=IF($A4="","",IFERROR(IF(INDEX(Experiments!$Q$2:$Q$61,MATCH($A4,Experiments!$A$2:$A$61,0))="","",INDEX(Experiments!$Q$2:$Q$61,MATCH($A4,Experiments!$A$2:$A$61,0))),""))}
B5: {=IF($A5="","",IFERROR(IF(INDEX(Experiments!$U$2:$U$61,MATCH($A5,Experiments!$A$2:$A$61,0))="","",INDEX(Experiments!$U$2:$U$61,MATCH($A5,Experiments!$A$2:$A$61,0))),""))} | C5: {=IF($A5="","",IFERROR(IF(INDEX(Experiments!$V$2:$V$61,MATCH($A5,Experiments!$A$2:$A$61,0))="","",INDEX(Experiments!$V$2:$V$61,MATCH($A5,Experiments!$A$2:$A$61,0))),""))} | D5: {=IF($A5="","",IFERROR(IF(INDEX(Experiments!$Q$2:$Q$61,MATCH($A5,Experiments!$A$2:$A$61,0))="","",INDEX(Experiments!$Q$2:$Q$61,MATCH($A5,Experiments!$A$2:$A$61,0))),""))}
B6: {=IF($A6="","",IFERROR(IF(INDEX(Experiments!$U$2:$U$61,MATCH($A6,Experiments!$A$2:$A$61,0))="","",INDEX(Experiments!$U$2:$U$61,MATCH($A6,Experiments!$A$2:$A$61,0))),""))} | C6: {=IF($A6="","",IFERROR(IF(INDEX(Experiments!$V$2:$V$61,MATCH($A6,Experiments!$A$2:$A$61,0))="","",INDEX(Experiments!$V$2:$V$61,MATCH($A6,Experiments!$A$2:$A$61,0))),""))} | D6: {=IF($A6="","",IFERROR(IF(INDEX(Experiments!$Q$2:$Q$61,MATCH($A6,Experiments!$A$2:$A$61,0))="","",INDEX(Experiments!$Q$2:$Q$61,MATCH($A6,Experiments!$A$2:$A$61,0))),""))}
A8: mean | B8: =IF(COUNT(B2:B6)=0,"",AVERAGE(B2:B6)) -> 0.90054001 | C8: =IF(COUNT(C2:C6)=0,"",AVERAGE(C2:C6)) -> 0.84613398 | D8: =IF(COUNT(D2:D6)=0,"",AVERAGE(D2:D6)) -> 0.24657943
A9: std (mẫu) | B9: =IF(COUNT(B2:B6)<2,"",STDEV(B2:B6)) -> 0.0014756429 | C9: =IF(COUNT(C2:C6)<2,"",STDEV(C2:C6)) -> 0.0014695178 | D9: =IF(COUNT(D2:D6)<2,"",STDEV(D2:D6)) -> 0.0035886743
A10: 2σ (ngưỡng nhiễu) | B10: =IF(B9="","",2*B9) -> 0.0029512858 | C10: =IF(C9="","",2*C9) -> 0.0029390356 | D10: =IF(D9="","",2*D9) -> 0.0071773486
A12: Nhập exp_id của các lần chạy baseline (khác seed) ở cột A. Cần ≥ 2 seed để có σ.
A13: Mọi chênh lệch nhỏ hơn 2σ không được coi là bằng chứng. Với ít seed, σ chỉ là ước lượng thô; nêu rõ trong báo cáo.

Sheet Summary
A1: group | B1: số dòng | C1: đã điền val_macro_f1 | D1: val_macro_f1 cao nhất | E1: val_macro_f1 thấp nhất | F1: val_acc cao nhất | G1: đã thử chủ đề này? | H1: nhận xét ngắn (bạn viết)
A2: baseline | B2: =COUNTIF(Experiments!$B$2:$B$61,A2) -> 2 | C2: =COUNTIFS(Experiments!$B$2:$B$61,A2,Experiments!$V$2:$V$61,"<>") -> 2 | D2: =IF(C2=0,"",MAXIFS(Experiments!$V$2:$V$61,Experiments!$B$2:$B$61,A2)) -> 0.84717309 | E2: =IF(C2=0,"",MINIFS(Experiments!$V$2:$V$61,Experiments!$B$2:$B$61,A2)) -> 0.84509488 | F2: =IF(C2=0,"",MAXIFS(Experiments!$U$2:$U$61,Experiments!$B$2:$B$61,A2)) -> 0.90158344 | G2: Có
A3: loss | B3: =COUNTIF(Experiments!$B$2:$B$61,A3) -> 1 | C3: =COUNTIFS(Experiments!$B$2:$B$61,A3,Experiments!$V$2:$V$61,"<>") -> 1 | D3: =IF(C3=0,"",MAXIFS(Experiments!$V$2:$V$61,Experiments!$B$2:$B$61,A3)) -> 0.70974256 | E3: =IF(C3=0,"",MINIFS(Experiments!$V$2:$V$61,Experiments!$B$2:$B$61,A3)) -> 0.70974256 | F3: =IF(C3=0,"",MAXIFS(Experiments!$U$2:$U$61,Experiments!$B$2:$B$61,A3)) -> 0.86117984 | G3: =IF(C3>0,"Có","Chưa") -> Có
A4: optimizer | B4: =COUNTIF(Experiments!$B$2:$B$61,A4) -> 3 | C4: =COUNTIFS(Experiments!$B$2:$B$61,A4,Experiments!$V$2:$V$61,"<>") -> 3 | D4: =IF(C4=0,"",MAXIFS(Experiments!$V$2:$V$61,Experiments!$B$2:$B$61,A4)) -> 0.87521444 | E4: =IF(C4=0,"",MINIFS(Experiments!$V$2:$V$61,Experiments!$B$2:$B$61,A4)) -> 0.74906728 | F4: =IF(C4=0,"",MAXIFS(Experiments!$U$2:$U$61,Experiments!$B$2:$B$61,A4)) -> 0.91567522 | G4: =IF(C4>0,"Có","Chưa") -> Có
A5: hparam | B5: =COUNTIF(Experiments!$B$2:$B$61,A5) -> 4 | C5: =COUNTIFS(Experiments!$B$2:$B$61,A5,Experiments!$V$2:$V$61,"<>") -> 4 | D5: =IF(C5=0,"",MAXIFS(Experiments!$V$2:$V$61,Experiments!$B$2:$B$61,A5)) -> 0.86214622 | E5: =IF(C5=0,"",MINIFS(Experiments!$V$2:$V$61,Experiments!$B$2:$B$61,A5)) -> 0.63139425 | F5: =IF(C5=0,"",MAXIFS(Experiments!$U$2:$U$61,Experiments!$B$2:$B$61,A5)) -> 0.91273854 | G5: =IF(C5>0,"Có","Chưa") -> Có
A6: dropout | B6: =COUNTIF(Experiments!$B$2:$B$61,A6) -> 1 | C6: =COUNTIFS(Experiments!$B$2:$B$61,A6,Experiments!$V$2:$V$61,"<>") -> 1 | D6: =IF(C6=0,"",MAXIFS(Experiments!$V$2:$V$61,Experiments!$B$2:$B$61,A6)) -> 0.76553455 | E6: =IF(C6=0,"",MINIFS(Experiments!$V$2:$V$61,Experiments!$B$2:$B$61,A6)) -> 0.76553455 | F6: =IF(C6=0,"",MAXIFS(Experiments!$U$2:$U$61,Experiments!$B$2:$B$61,A6)) -> 0.86140574 | G6: =IF(C6>0,"Có","Chưa") -> Có
A7: clipping | B7: =COUNTIF(Experiments!$B$2:$B$61,A7) -> 1 | C7: =COUNTIFS(Experiments!$B$2:$B$61,A7,Experiments!$V$2:$V$61,"<>") -> 1 | D7: =IF(C7=0,"",MAXIFS(Experiments!$V$2:$V$61,Experiments!$B$2:$B$61,A7)) -> 0.84404422 | E7: =IF(C7=0,"",MINIFS(Experiments!$V$2:$V$61,Experiments!$B$2:$B$61,A7)) -> 0.84404422 | F7: =IF(C7=0,"",MAXIFS(Experiments!$U$2:$U$61,Experiments!$B$2:$B$61,A7)) -> 0.90297111 | G7: =IF(C7>0,"Có","Chưa") -> Có
A8: amp | B8: =COUNTIF(Experiments!$B$2:$B$61,A8) -> 0 | C8: =COUNTIFS(Experiments!$B$2:$B$61,A8,Experiments!$V$2:$V$61,"<>") -> 0 | D8: =IF(C8=0,"",MAXIFS(Experiments!$V$2:$V$61,Experiments!$B$2:$B$61,A8)) | E8: =IF(C8=0,"",MINIFS(Experiments!$V$2:$V$61,Experiments!$B$2:$B$61,A8)) | F8: =IF(C8=0,"",MAXIFS(Experiments!$U$2:$U$61,Experiments!$B$2:$B$61,A8)) | G8: =IF(C8>0,"Có","Chưa") -> Chưa
A9: init | B9: =COUNTIF(Experiments!$B$2:$B$61,A9) -> 1 | C9: =COUNTIFS(Experiments!$B$2:$B$61,A9,Experiments!$V$2:$V$61,"<>") -> 1 | D9: =IF(C9=0,"",MAXIFS(Experiments!$V$2:$V$61,Experiments!$B$2:$B$61,A9)) -> 0.84507672 | E9: =IF(C9=0,"",MINIFS(Experiments!$V$2:$V$61,Experiments!$B$2:$B$61,A9)) -> 0.84507672 | F9: =IF(C9=0,"",MAXIFS(Experiments!$U$2:$U$61,Experiments!$B$2:$B$61,A9)) -> 0.90044319 | G9: =IF(C9>0,"Có","Chưa") -> Có
A10: final | B10: =COUNTIF(Experiments!$B$2:$B$61,A10) -> 0 | C10: =COUNTIFS(Experiments!$B$2:$B$61,A10,Experiments!$V$2:$V$61,"<>") -> 0 | D10: =IF(C10=0,"",MAXIFS(Experiments!$V$2:$V$61,Experiments!$B$2:$B$61,A10)) | E10: =IF(C10=0,"",MINIFS(Experiments!$V$2:$V$61,Experiments!$B$2:$B$61,A10)) | F10: =IF(C10=0,"",MAXIFS(Experiments!$U$2:$U$61,Experiments!$B$2:$B$61,A10)) | G10: —
A11: other | B11: =COUNTIF(Experiments!$B$2:$B$61,A11) -> 0 | C11: =COUNTIFS(Experiments!$B$2:$B$61,A11,Experiments!$V$2:$V$61,"<>") -> 0 | D11: =IF(C11=0,"",MAXIFS(Experiments!$V$2:$V$61,Experiments!$B$2:$B$61,A11)) | E11: =IF(C11=0,"",MINIFS(Experiments!$V$2:$V$61,Experiments!$B$2:$B$61,A11)) | F11: =IF(C11=0,"",MAXIFS(Experiments!$U$2:$U$61,Experiments!$B$2:$B$61,A11)) | G11: —
A13: Số chủ đề (trong 7) đã thử: | D13: =COUNTIF(G2:G11,"Có") -> 7
A14: 7 chủ đề: loss, optimizer, hparam, dropout, clipping, amp, init. Một chủ đề 'đã thử' khi có ≥ 1 dòng có val_macro_f1.
